Workbook

Sheet WACC Calc>

Sheet WACC
B2: Weighted Average Cost of Capital
B4: All figures are in PKR unless stated otherwise
B6: Peer Comps
H7: Debt/ | I7: Debt/ | J7: Levered | K7: Unlevered
B8: Name of the company | D8: Country | E8: Total Debt | F8: Total Equity | G8: Tax Rate 1 | H8: Equity | I8: Capital | J8: Beta 2 | K8: Beta 3
B10: ='Peer Comps'!B8 -> Fauji Fertilizer Company Limited | D10: Pakistan | E10: ='Peer Comps'!D8 -> 79894647 | F10: ='Peer Comps'!E8 -> 8.4908129e+08 | G10: ='Peer Comps'!F8 -> 0.39 | H10: =E10/F10 -> 0.094095404 | I10: =E10/(E10+F10) -> 0.086002925 | J10: ='Peer Comps'!J8 -> 0.84594614 | K10: =J10/(1+(1-G10)*H10) -> 0.80002609
B11: ='Peer Comps'!B9 -> Engro Fertilizers Limited | D11: Pakistan | E11: ='Peer Comps'!D9 -> 73205930 | F11: ='Peer Comps'!E9 -> 3.1798819e+08 | G11: ='Peer Comps'!F9 -> 0.39 | H11: =E11/F11 -> 0.23021587 | I11: =E11/(E11+F11) -> 0.18713453 | J11: ='Peer Comps'!J9 -> 0.88004126 | K11: =J11/(1+(1-G11)*H11) -> 0.77167381
B12: ='Peer Comps'!B10 -> Fatima Fertilizer Company Limited | D12: Pakistan | E12: ='Peer Comps'!D10 -> 67497376 | F12: ='Peer Comps'!E10 -> 393771000 | G12: ='Peer Comps'!F10 -> 0.39 | H12: =E12/F12 -> 0.17141277 | I12: =E12/(E12+F12) -> 0.14632994 | J12: ='Peer Comps'!J10 -> 0.78172323 | K12: =J12/(1+(1-G12)*H12) -> 0.7077225
F14: Average | G14: =IFERROR(AVERAGE(G10:G12),0) -> 0.39 | H14: =IFERROR(AVERAGE(H10:H12),0) -> 0.16524135 | I14: =IFERROR(AVERAGE(I10:I12),0) -> 0.13982247 | J14: =IFERROR(AVERAGE(J10:J12),0) -> 0.83590354 | K14: =IFERROR(AVERAGE(K10:K12),0) -> 0.75980746
F15: Median | G15: =IFERROR(MEDIAN(G10:G12),0) -> 0.39 | H15: =IFERROR(MEDIAN(H10:H12),0) -> 0.17141277 | I15: =IFERROR(MEDIAN(I10:I12),0) -> 0.14632994 | J15: =IFERROR(MEDIAN(J10:J12),0) -> 0.84594614 | K15: =IFERROR(MEDIAN(K10:K12),0) -> 0.77167381
B18: Cost of Debt | G18: Cost of Equity
B20: Pre Tax Cost of Debt | E20: =Rates!D6 -> 0.1225 | G20: Risk Free Rate | K20: 0.1105
B21: Tax Rate | E21: =G10 -> 0.39 | G21: Market Premium | K21: 0.06
B22: Post Tax Cost of Debt | E22: =IFERROR(E20*(1-E21),0) -> 0.074725 | G22: Levered Beta 4 | K22: =K31 -> 0.84818985
G23: Cost of Equity | K23: =K20+(K21*K22) -> 0.16139139
B26: Capital Structure | G26: Levered Beta
D28: Current | E28: Target | G28: Comps Median Unlevered Beta | K28: =K15 -> 0.77167381
B29: Total Debt | C29: =E10 -> 79894647 | D29: =C29/$C$31 -> 0.086002925 | E29: =I14 -> 0.13982247 | G29: Target Debt / Equity | K29: =E33 -> 0.16255071
B30: Market Capitalization | C30: =F10 -> 8.4908129e+08 | D30: =C30/$C$31 -> 0.91399708 | E30: =E31-E29 -> 0.86017753 | G30: Tax Rate | K30: =G14 -> 0.39
B31: Total Capitalization | C31: =SUM(C29:C30) -> 9.2897593e+08 | D31: =C31/$C$31 -> 1 | E31: =D31 -> 1 | G31: Levered Beta | K31: =K28*(1+(1-K30)*K29) -> 0.84818985
B33: Debt / Equity | D33: =D29/D30 -> 0.094095404 | E33: =E29/E30 -> 0.16255071 | G33: Weighted Average Cost of Capital
J35: Total Cost | K35: Total Weight
B36: 1 The effective tax rate taken includes Super tax | G36: Debt | J36: =E22 -> 0.074725 | K36: =E29 -> 0.13982247
B37: 2 The levered beta is calculated for 5 years weekly historical data | G37: Equity | J37: =K23 -> 0.16139139 | K37: =E30 -> 0.86017753
B38: 3 The unlevered beta = levered beta / (1+(1-tax)*(debt/equity)) | G38: Weighted Average Cost of Capital | K38: =SUMPRODUCT(J36:J37,K36:K37) -> 0.14927348
B40: Generated by Muhammad Haris Khan
B41: Connect on linkedin

Sheet Beta Calc>

Sheet FFC
B2: Regression Beta - 5 years
B4: FFC Weekly Returns
B6: Date | C6: Closing Price | D6: Returns | F6: Closing Price | G6: Returns | I6: Beta Drifting | N6: Beta by Slope | P6: =SLOPE(D8:D266,G8:G266) -> 0.77006887
B7: 44227 | C7: 110.71 | F7: 46905.79 | I7: Levered Raw Beta | K7: =P8 -> 0.77006887 | N7: Beta by Covariance | P7: =_xlfn.COVARIANCE.S(D7:D266,G7:G266)/_xlfn.VAR.S(G7:G266) -> 0.77006887
B8: 44234 | C8: 108.21 | D8: =C8/C7 -1 -> -0.022581519 | F8: 45808.36 | G8: =F8/F7 -1 -> -0.023396472 | I8: Raw Beta weight | K8: 0.67 | N8: Beta by regression | P8: =O27 -> 0.77006887
B9: 44241 | C9: 109.34 | D9: =C9/C8 -1 -> 0.010442658 | F9: 46227.65 | G9: =F9/F8 -1 -> 0.0091531327
B10: 44248 | C10: 110.75 | D10: =C10/C9 -1 -> 0.012895555 | F10: 45865.02 | G10: =F10/F9 -1 -> -0.0078444394 | I10: Market Beta | K10: 1 | N10: SUMMARY OUTPUT
B11: 44255 | C11: 109.73 | D11: =C11/C10 -1 -> -0.0092099323 | F11: 45837.35 | G11: =F11/F10 -1 -> -0.00060329201 | I11: Market Beta Weight | K11: 0.33
B12: 44262 | C12: 103.5 | D12: =C12/C11 -1 -> -0.056775722 | F12: 43788.08 | G12: =F12/F11 -1 -> -0.044707427 | N12: Regression Statistics
B13: 44269 | C13: 104.95 | D13: =C13/C12 -1 -> 0.014009662 | F13: 44901.31 | G13: =F13/F12 -1 -> 0.025423129 | I13: Adjusted Beta | K13: =(K7*K8) + (K10*K11) -> 0.84594614 | N13: Multiple R | O13: 0.52696046
B14: 44276 | C14: 105.43 | D14: =C14/C13 -1 -> 0.0045736065 | F14: 45521.63 | G14: =F14/F13 -1 -> 0.013815187 | N14: R Square | O14: 0.27768732
B15: 44283 | C15: 104.45 | D15: =C15/C14 -1 -> -0.009295267 | F15: 44300.95 | G15: =F15/F14 -1 -> -0.026815384 | N15: Adjusted R Square | O15: 0.27487677
B16: 44290 | C16: 102.5 | D16: =C16/C15 -1 -> -0.01866922 | F16: 45186.48 | G16: =F16/F15 -1 -> 0.019988962 | N16: Standard Error | O16: 0.030554162
B17: 44297 | C17: 106 | D17: =C17/C16 -1 -> 0.034146341 | F17: 45305.63 | G17: =F17/F16 -1 -> 0.0026368507 | N17: Observations | O17: 259
B18: 44304 | C18: 103.5 | D18: =C18/C17 -1 -> -0.023584906 | F18: 44706.76 | G18: =F18/F17 -1 -> -0.013218445
B19: 44311 | C19: 105 | D19: =C19/C18 -1 -> 0.014492754 | F19: 44262.35 | G19: =F19/F18 -1 -> -0.0099405549 | N19: ANOVA
B20: 44318 | C20: 108 | D20: =C20/C19 -1 -> 0.028571429 | F20: 45174.67 | G20: =F20/F19 -1 -> 0.020611649 | O20: df | P20: SS | Q20: MS | R20: F | S20: Significance F
B21: 44332 | C21: 108.66 | D21: =C21/C20 -1 -> 0.0061111111 | F21: 45914.98 | G21: =F21/F20 -1 -> 0.016387723 | N21: Regression | O21: 1 | P21: 0.092236897 | Q21: 0.092236897 | R21: 98.801591 | S21: 6.5570413e-20
B22: 44339 | C22: 107.99 | D22: =C22/C21 -1 -> -0.0061660225 | F22: 47126.29 | G22: =F22/F21 -1 -> 0.026381586 | N22: Residual | O22: 257 | P22: 0.2399241 | Q22: 0.0009335568
B23: 44346 | C23: 107.5 | D23: =C23/C22 -1 -> -0.0045374572 | F23: 48211.7 | G23: =F23/F22 -1 -> 0.023031942 | N23: Total | O23: 258 | P23: 0.332161
B24: 44353 | C24: 106.82 | D24: =C24/C23 -1 -> -0.0063255814 | F24: 48304.72 | G24: =F24/F23 -1 -> 0.0019294072
B25: 44360 | C25: 106.93 | D25: =C25/C24 -1 -> 0.0010297697 | F25: 48238.67 | G25: =F25/F24 -1 -> -0.0013673612 | O25: Coefficients | P25: Standard Error | Q25: t Stat | R25: P-value | S25: Lower 95% | T25: Upper 95% | U25: Lower 95.0% | V25: Upper 95.0%
B26: 44367 | C26: 107 | D26: =C26/C25 -1 -> 0.00065463387 | F26: 47703.94 | G26: =F26/F25 -1 -> -0.01108509 | N26: Intercept | O26: 0.0027822333 | P26: 0.0019472916 | Q26: 1.4287708 | R26: 0.15428438 | S26: -0.0010524463 | T26: 0.0066169129 | U26: -0.0010524463 | V26: 0.0066169129
B27: 44374 | C27: 106.9 | D27: =C27/C26 -1 -> -0.00093457944 | F27: 47686.18 | G27: =F27/F26 -1 -> -0.00037229629 | N27: X Variable 1 | O27: 0.77006887 | P27: 0.077472505 | Q27: 9.9398989 | R27: 6.5570413e-20 | S27: 0.61750711 | T27: 0.92263063 | U27: 0.61750711 | V27: 0.92263063
B28: 44381 | C28: 107 | D28: =C28/C27 -1 -> 0.0009354537 | F28: 47563.45 | G28: =F28/F27 -1 -> -0.0025737016
B29: 44388 | C29: 106.95 | D29: =C29/C28 -1 -> -0.00046728972 | F29: 47834.33 | G29: =F29/F28 -1 -> 0.0056951293
B30: 44395 | C30: 107.85 | D30: =C30/C29 -1 -> 0.0084151473 | F30: 47793.07 | G30: =F30/F29 -1 -> -0.00086256042 | N30: Debt Calculations
B31: 44402 | C31: 106.5 | D31: =C31/C30 -1 -> -0.012517385 | F31: 47055.29 | G31: =F31/F30 -1 -> -0.015436966
B32: 44409 | C32: 106.45 | D32: =C32/C31 -1 -> -0.00046948357 | F32: 47489.95 | G32: =F32/F31 -1 -> 0.0092372186 | N32: Long term borrowings - secured | P32: 50250000
B33: 44416 | C33: 106.2 | D33: =C33/C32 -1 -> -0.0023485204 | F33: 47169.84 | G33: =F33/F32 -1 -> -0.0067405841 | N33: Short term borrowing secured | P33: 18594647
B34: 44423 | C34: 107 | D34: =C34/C33 -1 -> 0.0075329567 | F34: 47599.82 | G34: =F34/F33 -1 -> 0.0091155705 | N34: Current portion of LT borrowing - secured | P34: 11050000
B35: 44430 | C35: 105.35 | D35: =C35/C34 -1 -> -0.015420561 | F35: 47136.53 | G35: =F35/F34 -1 -> -0.00973302 | P35: =SUM(P32:P34) -> 79894647
B36: 44437 | C36: 105.76 | D36: =C36/C35 -1 -> 0.0038917893 | F36: 46957.47 | G36: =F36/F35 -1 -> -0.0037987523
B37: 44444 | C37: 106.05 | D37: =C37/C36 -1 -> 0.0027420575 | F37: 47198.29 | G37: =F37/F36 -1 -> 0.0051284705 | N37: https://dps.psx.com.pk/download/document/269389.pdf
B38: 44451 | C38: 109.04 | D38: =C38/C37 -1 -> 0.028194248 | F38: 46636.08 | G38: =F38/F37 -1 -> -0.01191166
B39: 44458 | C39: 104.01 | D39: =C39/C38 -1 -> -0.046129861 | F39: 45073.52 | G39: =F39/F38 -1 -> -0.033505389
B40: 44465 | C40: 101.5 | D40: =C40/C39 -1 -> -0.024132295 | F40: 44871.7 | G40: =F40/F39 -1 -> -0.0044775735
B41: 44472 | C41: 98.9 | D41: =C41/C40 -1 -> -0.025615764 | F41: 44477.23 | G41: =F41/F40 -1 -> -0.0087910643
B42: 44479 | C42: 100.4 | D42: =C42/C41 -1 -> 0.015166835 | F42: 44821.53 | G42: =F42/F41 -1 -> 0.0077410396
B43: 44486 | C43: 99.55 | D43: =C43/C42 -1 -> -0.0084661355 | F43: 45578.36 | G43: =F43/F42 -1 -> 0.016885412
...

Sheet Engro
B2: Regression Beta - 5 years
B4: Engro Fertilizers Weekly Returns | N4: Beta by slope | P4: =SLOPE(D8:D266,G8:G266) -> 0.82095711
N5: Beta by covariance | P5: =_xlfn.COVARIANCE.S(D8:D266,G8:G266)/_xlfn.VAR.S(G8:G266) -> 0.82095711
B6: Date | C6: Closing Price | D6: Returns | F6: Closing Price | G6: Returns | I6: Beta Drifting | N6: Beta by Regression | P6: =O25 -> 0.82095711
B7: 44227 | C7: 64.9 | F7: 46905.79 | I7: Levered Raw Beta | K7: =P6 -> 0.82095711
B8: 44234 | C8: 63.29 | D8: =C8/C7 -1 -> -0.024807396 | F8: 45808.36 | G8: =F8/F7 -1 -> -0.023396472 | I8: Raw Beta weight | K8: 0.67 | N8: SUMMARY OUTPUT
B9: 44241 | C9: 65.1 | D9: =C9/C8 -1 -> 0.028598515 | F9: 46227.65 | G9: =F9/F8 -1 -> 0.0091531327
B10: 44248 | C10: 65.16 | D10: =C10/C9 -1 -> 0.00092165899 | F10: 45865.02 | G10: =F10/F9 -1 -> -0.0078444394 | I10: Market Beta | K10: 1 | N10: Regression Statistics
B11: 44255 | C11: 65.78 | D11: =C11/C10 -1 -> 0.0095150399 | F11: 45837.35 | G11: =F11/F10 -1 -> -0.00060329201 | I11: Market Beta Weight | K11: 0.33 | N11: Multiple R | O11: 0.56642249
B12: 44262 | C12: 64.47 | D12: =C12/C11 -1 -> -0.019914868 | F12: 43788.08 | G12: =F12/F11 -1 -> -0.044707427 | N12: R Square | O12: 0.32083443
B13: 44269 | C13: 62.59 | D13: =C13/C12 -1 -> -0.02916085 | F13: 44901.31 | G13: =F13/F12 -1 -> 0.025423129 | I13: Adjusted Beta | K13: =(K7*K8) + (K10*K11) -> 0.88004126 | N13: Adjusted R Square | O13: 0.31819177
B14: 44276 | C14: 62.59 | D14: =C14/C13 -1 -> 0 | F14: 45521.63 | G14: =F14/F13 -1 -> 0.013815187 | N14: Standard Error | O14: 0.029384887
B15: 44283 | C15: 62.55 | D15: =C15/C14 -1 -> -0.00063907973 | F15: 44300.95 | G15: =F15/F14 -1 -> -0.026815384 | N15: Observations | O15: 259
B16: 44290 | C16: 62.25 | D16: =C16/C15 -1 -> -0.0047961631 | F16: 45186.48 | G16: =F16/F15 -1 -> 0.019988962
B17: 44297 | C17: 63.85 | D17: =C17/C16 -1 -> 0.025702811 | F17: 45305.63 | G17: =F17/F16 -1 -> 0.0026368507 | N17: ANOVA
B18: 44304 | C18: 66 | D18: =C18/C17 -1 -> 0.03367267 | F18: 44706.76 | G18: =F18/F17 -1 -> -0.013218445 | O18: df | P18: SS | Q18: MS | R18: F | S18: Significance F
B19: 44311 | C19: 67 | D19: =C19/C18 -1 -> 0.015151515 | F19: 44262.35 | G19: =F19/F18 -1 -> -0.0099405549 | N19: Regression | O19: 1 | P19: 0.10483022 | Q19: 0.10483022 | R19: 121.40552 | S19: 2.232556e-23
B20: 44318 | C20: 67.9 | D20: =C20/C19 -1 -> 0.013432836 | F20: 45174.67 | G20: =F20/F19 -1 -> 0.020611649 | N20: Residual | O20: 257 | P20: 0.2219122 | Q20: 0.0008634716
B21: 44332 | C21: 68.3 | D21: =C21/C20 -1 -> 0.0058910162 | F21: 45914.98 | G21: =F21/F20 -1 -> 0.016387723 | N21: Total | O21: 258 | P21: 0.32674242
B22: 44339 | C22: 70.88 | D22: =C22/C21 -1 -> 0.037774524 | F22: 47126.29 | G22: =F22/F21 -1 -> 0.026381586
B23: 44346 | C23: 72.02 | D23: =C23/C22 -1 -> 0.016083521 | F23: 48211.7 | G23: =F23/F22 -1 -> 0.023031942 | O23: Coefficients | P23: Standard Error | Q23: t Stat | R23: P-value | S23: Lower 95% | T23: Upper 95% | U23: Lower 95.0% | V23: Upper 95.0%
B24: 44353 | C24: 72.1 | D24: =C24/C23 -1 -> 0.0011108026 | F24: 48304.72 | G24: =F24/F23 -1 -> 0.0019294072 | N24: Intercept | O24: 0.001164579 | P24: 0.0018727708 | Q24: 0.62184809 | R24: 0.53459301 | S24: -0.0025233516 | T24: 0.0048525095 | U24: -0.0025233516 | V24: 0.0048525095
B25: 44360 | C25: 69.6 | D25: =C25/C24 -1 -> -0.034674064 | F25: 48238.67 | G25: =F25/F24 -1 -> -0.0013673612 | N25: X Variable 1 | O25: 0.82095711 | P25: 0.074507716 | Q25: 11.018417 | R25: 2.232556e-23 | S25: 0.67423372 | T25: 0.9676805 | U25: 0.67423372 | V25: 0.9676805
B26: 44367 | C26: 70.5 | D26: =C26/C25 -1 -> 0.012931034 | F26: 47703.94 | G26: =F26/F25 -1 -> -0.01108509
B27: 44374 | C27: 70.86 | D27: =C27/C26 -1 -> 0.005106383 | F27: 47686.18 | G27: =F27/F26 -1 -> -0.00037229629
B28: 44381 | C28: 73 | D28: =C28/C27 -1 -> 0.030200395 | F28: 47563.45 | G28: =F28/F27 -1 -> -0.0025737016 | N28: Debt Calculations
B29: 44388 | C29: 71.9 | D29: =C29/C28 -1 -> -0.015068493 | F29: 47834.33 | G29: =F29/F28 -1 -> 0.0056951293
B30: 44395 | C30: 72.37 | D30: =C30/C29 -1 -> 0.0065368567 | F30: 47793.07 | G30: =F30/F29 -1 -> -0.00086256042 | N30: Borrowings | P30: 33271430
B31: 44402 | C31: 76.1 | D31: =C31/C30 -1 -> 0.051540694 | F31: 47055.29 | G31: =F31/F30 -1 -> -0.015436966 | N31: Short-term borrowings | P31: 28100170
B32: 44409 | C32: 77.38 | D32: =C32/C31 -1 -> 0.016819974 | F32: 47489.95 | G32: =F32/F31 -1 -> 0.0092372186 | N32: Current portion of borrowings | P32: 11834330
B33: 44416 | C33: 76.18 | D33: =C33/C32 -1 -> -0.015507883 | F33: 47169.84 | G33: =F33/F32 -1 -> -0.0067405841 | P33: =SUM(P30:P32) -> 73205930
B34: 44423 | C34: 77.41 | D34: =C34/C33 -1 -> 0.01614597 | F34: 47599.82 | G34: =F34/F33 -1 -> 0.0091155705
B35: 44430 | C35: 77.1 | D35: =C35/C34 -1 -> -0.0040046506 | F35: 47136.53 | G35: =F35/F34 -1 -> -0.00973302
B36: 44437 | C36: 77.1 | D36: =C36/C35 -1 -> 0 | F36: 46957.47 | G36: =F36/F35 -1 -> -0.0037987523
B37: 44444 | C37: 74.01 | D37: =C37/C36 -1 -> -0.040077821 | F37: 47198.29 | G37: =F37/F36 -1 -> 0.0051284705
B38: 44451 | C38: 72.9 | D38: =C38/C37 -1 -> -0.014997973 | F38: 46636.08 | G38: =F38/F37 -1 -> -0.01191166
B39: 44458 | C39: 71.99 | D39: =C39/C38 -1 -> -0.012482853 | F39: 45073.52 | G39: =F39/F38 -1 -> -0.033505389
B40: 44465 | C40: 70.05 | D40: =C40/C39 -1 -> -0.026948187 | F40: 44871.7 | G40: =F40/F39 -1 -> -0.0044775735
B41: 44472 | C41: 70.74 | D41: =C41/C40 -1 -> 0.0098501071 | F41: 44477.23 | G41: =F41/F40 -1 -> -0.0087910643
B42: 44479 | C42: 71.88 | D42: =C42/C41 -1 -> 0.016115352 | F42: 44821.53 | G42: =F42/F41 -1 -> 0.0077410396
...

Sheet Fatima
B2: Regression Beta - 5 years
B4: Engro Fertilizers Weekly Returns
B6: Date | C6: Closing Price | D6: Returns | F6: Closing Price | G6: Returns | I6: Beta Drifting | N6: Beta by slope | P6: =SLOPE(D8:D266,G8:G266) -> 0.67421377
B7: 44227 | C7: 30 | F7: 46905.79 | I7: Levered Raw Beta | K7: =P8 -> 0.67421377 | N7: Beta by covariance | P7: =_xlfn.COVARIANCE.S(D8:D266,G8:G266)/_xlfn.VAR.S(G8:G266) -> 0.67421377
B8: 44234 | C8: 28.55 | D8: =C8/C7 -1 -> -0.048333333 | F8: 45808.36 | G8: =F8/F7 -1 -> -0.023396472 | I8: Raw Beta weight | K8: 0.67 | N8: Beta by regression | P8: =O28 -> 0.67421377
B9: 44241 | C9: 28.8 | D9: =C9/C8 -1 -> 0.0087565674 | F9: 46227.65 | G9: =F9/F8 -1 -> 0.0091531327
B10: 44248 | C10: 28.4 | D10: =C10/C9 -1 -> -0.013888889 | F10: 45865.02 | G10: =F10/F9 -1 -> -0.0078444394 | I10: Market Beta | K10: 1
B11: 44255 | C11: 29 | D11: =C11/C10 -1 -> 0.021126761 | F11: 45837.35 | G11: =F11/F10 -1 -> -0.00060329201 | I11: Market Beta Weight | K11: 0.33 | N11: SUMMARY OUTPUT
B12: 44262 | C12: 28.75 | D12: =C12/C11 -1 -> -0.0086206897 | F12: 43788.08 | G12: =F12/F11 -1 -> -0.044707427
B13: 44269 | C13: 28.9 | D13: =C13/C12 -1 -> 0.0052173913 | F13: 44901.31 | G13: =F13/F12 -1 -> 0.025423129 | I13: Adjusted Beta | K13: =(K7*K8) + (K10*K11) -> 0.78172323 | N13: Regression Statistics
B14: 44276 | C14: 29.5 | D14: =C14/C13 -1 -> 0.020761246 | F14: 45521.63 | G14: =F14/F13 -1 -> 0.013815187 | N14: Multiple R | O14: 0.44170104
B15: 44283 | C15: 29.25 | D15: =C15/C14 -1 -> -0.0084745763 | F15: 44300.95 | G15: =F15/F14 -1 -> -0.026815384 | N15: R Square | O15: 0.19509981
B16: 44290 | C16: 29 | D16: =C16/C15 -1 -> -0.0085470085 | F16: 45186.48 | G16: =F16/F15 -1 -> 0.019988962 | N16: Adjusted R Square | O16: 0.1919679
B17: 44297 | C17: 27.09 | D17: =C17/C16 -1 -> -0.065862069 | F17: 45305.63 | G17: =F17/F16 -1 -> 0.0026368507 | N17: Standard Error | O17: 0.033689644
B18: 44304 | C18: 26.2 | D18: =C18/C17 -1 -> -0.032853451 | F18: 44706.76 | G18: =F18/F17 -1 -> -0.013218445 | N18: Observations | O18: 259
B19: 44311 | C19: 26.2 | D19: =C19/C18 -1 -> 0 | F19: 44262.35 | G19: =F19/F18 -1 -> -0.0099405549
B20: 44318 | C20: 26.19 | D20: =C20/C19 -1 -> -0.00038167939 | F20: 45174.67 | G20: =F20/F19 -1 -> 0.020611649 | N20: ANOVA
B21: 44332 | C21: 27.3 | D21: =C21/C20 -1 -> 0.042382589 | F21: 45914.98 | G21: =F21/F20 -1 -> 0.016387723 | O21: df | P21: SS | Q21: MS | R21: F | S21: Significance F
B22: 44339 | C22: 29.25 | D22: =C22/C21 -1 -> 0.071428571 | F22: 47126.29 | G22: =F22/F21 -1 -> 0.026381586 | N22: Regression | O22: 1 | P22: 0.07070348 | Q22: 0.07070348 | R22: 62.294246 | S22: 8.5626783e-14
B23: 44346 | C23: 28.75 | D23: =C23/C22 -1 -> -0.017094017 | F23: 48211.7 | G23: =F23/F22 -1 -> 0.023031942 | N23: Residual | O23: 257 | P23: 0.29169298 | Q23: 0.0011349921
B24: 44353 | C24: 29.1 | D24: =C24/C23 -1 -> 0.012173913 | F24: 48304.72 | G24: =F24/F23 -1 -> 0.0019294072 | N24: Total | O24: 258 | P24: 0.36239646
B25: 44360 | C25: 28.51 | D25: =C25/C24 -1 -> -0.020274914 | F25: 48238.67 | G25: =F25/F24 -1 -> -0.0013673612
B26: 44367 | C26: 28.87 | D26: =C26/C25 -1 -> 0.012627148 | F26: 47703.94 | G26: =F26/F25 -1 -> -0.01108509 | O26: Coefficients | P26: Standard Error | Q26: t Stat | R26: P-value | S26: Lower 95% | T26: Upper 95% | U26: Lower 95.0% | V26: Upper 95.0%
B27: 44374 | C27: 28.75 | D27: =C27/C26 -1 -> -0.0041565639 | F27: 47686.18 | G27: =F27/F26 -1 -> -0.00037229629 | N27: Intercept | O27: 0.0036583438 | P27: 0.0021471236 | Q27: 1.7038348 | R27: 0.089620688 | S27: -0.00056985242 | T27: 0.00788654 | U27: -0.00056985242 | V27: 0.00788654
B28: 44381 | C28: 28.6 | D28: =C28/C27 -1 -> -0.0052173913 | F28: 47563.45 | G28: =F28/F27 -1 -> -0.0025737016 | N28: X Variable 1 | O28: 0.67421377 | P28: 0.08542277 | Q28: 7.8926704 | R28: 8.5626783e-14 | S28: 0.50599605 | T28: 0.84243149 | U28: 0.50599605 | V28: 0.84243149
B29: 44388 | C29: 28.25 | D29: =C29/C28 -1 -> -0.012237762 | F29: 47834.33 | G29: =F29/F28 -1 -> 0.0056951293
B30: 44395 | C30: 28.58 | D30: =C30/C29 -1 -> 0.011681416 | F30: 47793.07 | G30: =F30/F29 -1 -> -0.00086256042
B31: 44402 | C31: 28.2 | D31: =C31/C30 -1 -> -0.013296011 | F31: 47055.29 | G31: =F31/F30 -1 -> -0.015436966 | N31: Debt Calculations
B32: 44409 | C32: 28.4 | D32: =C32/C31 -1 -> 0.0070921986 | F32: 47489.95 | G32: =F32/F31 -1 -> 0.0092372186
B33: 44416 | C33: 28.15 | D33: =C33/C32 -1 -> -0.0088028169 | F33: 47169.84 | G33: =F33/F32 -1 -> -0.0067405841 | N33: Long term Debt financing secured | P33: 3175575
B34: 44423 | C34: 28.14 | D34: =C34/C33 -1 -> -0.00035523979 | F34: 47599.82 | G34: =F34/F33 -1 -> 0.0091155705 | N34: Short term Debt financing secured | P34: 26394701
B35: 44430 | C35: 29.78 | D35: =C35/C34 -1 -> 0.058280028 | F35: 47136.53 | G35: =F35/F34 -1 -> -0.00973302 | N35: Current portion of LT financing | P35: 37927100
B36: 44437 | C36: 29.52 | D36: =C36/C35 -1 -> -0.0087306917 | F36: 46957.47 | G36: =F36/F35 -1 -> -0.0037987523 | P36: =SUM(P33:P35) -> 67497376
B37: 44444 | C37: 30.5 | D37: =C37/C36 -1 -> 0.033197832 | F37: 47198.29 | G37: =F37/F36 -1 -> 0.0051284705
B38: 44451 | C38: 29.5 | D38: =C38/C37 -1 -> -0.032786885 | F38: 46636.08 | G38: =F38/F37 -1 -> -0.01191166
B39: 44458 | C39: 28.56 | D39: =C39/C38 -1 -> -0.031864407 | F39: 45073.52 | G39: =F39/F38 -1 -> -0.033505389
B40: 44465 | C40: 30.2 | D40: =C40/C39 -1 -> 0.057422969 | F40: 44871.7 | G40: =F40/F39 -1 -> -0.0044775735
B41: 44472 | C41: 29.85 | D41: =C41/C40 -1 -> -0.011589404 | F41: 44477.23 | G41: =F41/F40 -1 -> -0.0087910643
B42: 44479 | C42: 29.6 | D42: =C42/C41 -1 -> -0.0083752094 | F42: 44821.53 | G42: =F42/F41 -1 -> 0.0077410396
B43: 44486 | C43: 30 | D43: =C43/C42 -1 -> 0.013513514 | F43: 45578.36 | G43: =F43/F42 -1 -> 0.016885412
...

Sheet Peer Comps
B2: Peer - Comps
B3: All values in PKR ---000'
B5: Peer Comps
G6: Debt/ | H6: Debt/ | I6: Levered Beta | J6: Levered Beta | K6: Unlevered
B7: Companies | D7: Total Debt | E7: Total Equity | F7: Tax Rate | G7: Equity | H7: Capital | I7: Before driffting | J7: After Drifting | K7: Beta
B8: Fauji Fertilizer Company Limited | D8: =FFC!P35 -> 79894647 | E8: 8.4908129e+08 | F8: 0.39 | G8: =D8/E8 -> 0.094095404 | H8: =D8/(D8+E8) -> 0.086002925 | I8: =FFC!P8 -> 0.77006887 | J8: =FFC!K13 -> 0.84594614 | K8: =J8/((1+(1-F8)*(G8))) -> 0.80002609
B9: Engro Fertilizers Limited | D9: =Engro!P33 -> 73205930 | E9: 3.1798819e+08 | F9: 0.39 | G9: =D9/E9 -> 0.23021587 | H9: =D9/(D9+E9) -> 0.18713453 | I9: =Engro!P6 -> 0.82095711 | J9: =Engro!K13 -> 0.88004126 | K9: =J9/((1+(1-F9)*(G9))) -> 0.77167381
B10: Fatima Fertilizer Company Limited | D10: =Fatima!P36 -> 67497376 | E10: 393771000 | F10: 0.39 | G10: =D10/E10 -> 0.17141277 | H10: =D10/(D10+E10) -> 0.14632994 | I10: =Fatima!P8 -> 0.67421377 | J10: =Fatima!K13 -> 0.78172323 | K10: =J10/((1+(1-F10)*(G10))) -> 0.7077225
E12: Average | F12: =IFERROR(AVERAGE(F8:F10),0) -> 0.39 | G12: =IFERROR(AVERAGE(G8:G10),0) -> 0.16524135 | H12: =IFERROR(AVERAGE(H8:H10),0) -> 0.13982247 | I12: =IFERROR(AVERAGE(I8:I10),0) -> 0.75507992 | J12: =IFERROR(AVERAGE(J8:J10),0) -> 0.83590354 | K12: =IFERROR(AVERAGE(K8:K10),0) -> 0.75980746
E13: Median | F13: =IFERROR(MEDIAN(F8:F10),0) -> 0.39 | G13: =IFERROR(MEDIAN(G8:G10),0) -> 0.17141277 | H13: =IFERROR(MEDIAN(H8:H10),0) -> 0.14632994 | I13: =IFERROR(MEDIAN(I8:I10),0) -> 0.77006887 | J13: =IFERROR(MEDIAN(J8:J10),0) -> 0.84594614 | K13: =IFERROR(MEDIAN(K8:K10),0) -> 0.77167381

Sheet Rates
B2: Cost of debt
B4: Kibor rate | D4: 0.105
B5: Spread | D5: 0.0175
B6: Pre tax xost of debt | D6: =SUM(D4:D5) -> 0.1225
